<?xml version="1.0" encoding="utf-8"?>
<!-- This URDF was automatically created by SolidWorks to URDF Exporter! Originally created by Stephen Brawner (brawner@gmail.com) 
     Commit Version: 1.6.0-4-g7f85cfe  Build Version: 1.6.7995.38578
     For more information, please see http://wiki.ros.org/sw_urdf_exporter -->
<robot
  name="mobile_robot_urdf">
  <link
    name="base_footlink">
    <inertial>
      <origin
        xyz="0.0158277968404401 -0.00151927738861557 0.0491376227857992"
        rpy="0 0 0" />
      <mass
        value="1.26164162297982" />
      <inertia
        ixx="0.0055916265743522"
        ixy="1.29976054416447E-06"
        ixz="5.20652580121554E-05"
        iyy="0.00700570051915985"
        iyz="-4.31719493973746E-07"
        izz="0.0120377937635135" />
    </inertial>
    <visual>
      <origin
        xyz="0 0 0"
        rpy="0 0 0" />
      <geometry>
        <mesh
          filename="package://mobile_robot_urdf/meshes/base_footlink.STL" />
      </geometry>
      <material
        name="">
        <color
          rgba="0.792156862745098 0.819607843137255 0.933333333333333 1" />
      </material>
    </visual>
    <collision>
      <origin
        xyz="0 0 0"
        rpy="0 0 0" />
      <geometry>
        <mesh
          filename="package://mobile_robot_urdf/meshes/base_footlink.STL" />
      </geometry>
    </collision>
  </link>
  <link
    name="base_link">
    <inertial>
      <origin
        xyz="0.0158113057544982 -0.00142019642296151 0.0301376227857992"
        rpy="0 0 0" />
      <mass
        value="1.26164162297982" />
      <inertia
        ixx="0.0055916265743519"
        ixy="1.29976054416347E-06"
        ixz="5.20652580120081E-05"
        iyy="0.0070057005191591"
        iyz="-4.31719493973544E-07"
        izz="0.012037793763513" />
    </inertial>
    <visual>
      <origin
        xyz="0 0 0"
        rpy="0 0 0" />
      <geometry>
        <mesh
          filename="package://mobile_robot_urdf/meshes/base_link.STL" />
      </geometry>
      <material
        name="">
        <color
          rgba="0.792156862745098 0.819607843137255 0.933333333333333 1" />
      </material>
    </visual>
    <collision>
      <origin
        xyz="0 0 0"
        rpy="0 0 0" />
      <geometry>
        <mesh
          filename="package://mobile_robot_urdf/meshes/base_link.STL" />
      </geometry>
    </collision>
  </link>
  <joint
    name="base_link_jt"
    type="fixed">
    <origin
      xyz="1.64910859419554E-05 -9.90809656540581E-05 0.019"
      rpy="0 0 0" />
    <parent
      link="base_footlink" />
    <child
      link="base_link" />
    <axis
      xyz="0 0 0" />
  </joint>
  <link
    name="Wheel_Left">
    <inertial>
      <origin
        xyz="6.84306026305093E-06 -0.0087833750304501 5.97320507063348E-06"
        rpy="0 0 0" />
      <mass
        value="0.0444228549621078" />
      <inertia
        ixx="2.01463395995947E-05"
        ixy="-1.97902606326091E-10"
        ixz="6.95168400298386E-09"
        iyy="3.55612270305918E-05"
        iyz="1.34479474223712E-10"
        izz="2.01421687267013E-05" />
    </inertial>
    <visual>
      <origin
        xyz="0 0 0"
        rpy="0 0 0" />
      <geometry>
        <mesh
          filename="package://mobile_robot_urdf/meshes/Wheel_Left.STL" />
      </geometry>
      <material
        name="">
        <color
          rgba="0.792156862745098 0.819607843137255 0.933333333333333 1" />
      </material>
    </visual>
    <collision>
      <origin
        xyz="0 0 0"
        rpy="0 0 0" />
      <geometry>
        <mesh
          filename="package://mobile_robot_urdf/meshes/Wheel_Left.STL" />
      </geometry>
    </collision>
  </link>
  <joint
    name="Wheel_Left_jt"
    type="continuous">
    <origin
      xyz="0.00102062400282479 0.1065 0.013"
      rpy="0 0 0" />
    <parent
      link="base_link" />
    <child
      link="Wheel_Left" />
    <axis
      xyz="0.035691530512416 0.999362854347549 0" />
  </joint>
  <link
    name="Wheel_Right">
    <inertial>
      <origin
        xyz="-6.7789E-06 0.0087834 -6.0459E-06"
        rpy="0 0 0" />
      <mass
        value="0.044423" />
      <inertia
        ixx="2.0144E-05"
        ixy="1.0879E-10"
        ixz="7.2514E-09"
        iyy="3.5561E-05"
        iyz="-2.1311E-10"
        izz="2.0145E-05" />
    </inertial>
    <visual>
      <origin
        xyz="0 0 0"
        rpy="0 0 0" />
      <geometry>
        <mesh
          filename="package://mobile_robot_urdf/meshes/Wheel_Right.STL" />
      </geometry>
      <material
        name="">
        <color
          rgba="0.79216 0.81961 0.93333 1" />
      </material>
    </visual>
    <collision>
      <origin
        xyz="0 0 0"
        rpy="0 0 0" />
      <geometry>
        <mesh
          filename="package://mobile_robot_urdf/meshes/Wheel_Right.STL" />
      </geometry>
    </collision>
  </link>
  <joint
    name="Wheel_Right_jt"
    type="continuous">
    <origin
      xyz="-0.000979375997175846 -0.1065 0.013"
      rpy="0 0 0" />
    <parent
      link="base_link" />
    <child
      link="Wheel_Right" />
    <axis
      xyz="0.035691530512416 0.999362854347549 0" />
  </joint>
  <link
    name="MT_behind_Left">
    <inertial>
      <origin
        xyz="0 2.77555756156289E-17 0.0127957030881675"
        rpy="0 0 0" />
      <mass
        value="0.0114608893813283" />
      <inertia
        ixx="9.23796782399639E-07"
        ixy="-5.20030943414897E-14"
        ixz="-1.54307092847888E-21"
        iyy="8.8589629868825E-07"
        iyz="4.33190414016163E-23"
        izz="1.34461458261358E-06" />
    </inertial>
    <visual>
      <origin
        xyz="0 0 0"
        rpy="0 0 0" />
      <geometry>
        <mesh
          filename="package://mobile_robot_urdf/meshes/MT_behind_Left.STL" />
      </geometry>
      <material
        name="">
        <color
          rgba="0.690196078431373 0.658823529411765 0.63921568627451 1" />
      </material>
    </visual>
    <collision>
      <origin
        xyz="0 0 0"
        rpy="0 0 0" />
      <geometry>
        <mesh
          filename="package://mobile_robot_urdf/meshes/MT_behind_Left.STL" />
      </geometry>
    </collision>
  </link>
  <joint
    name="MT_behind_Left_jt"
    type="fixed">
    <origin
      xyz="-0.109979375997175 0.0950000000000006 -0.0190000000000004"
      rpy="0 0 0" />
    <parent
      link="base_link" />
    <child
      link="MT_behind_Left" />
    <axis
      xyz="0 0 0" />
  </joint>
  <link
    name="MT_behind_Right">
    <inertial>
      <origin
        xyz="1.11022302462516E-16 5.55111512312578E-17 0.0127957030881676"
        rpy="0 0 0" />
      <mass
        value="0.0114608893813283" />
      <inertia
        ixx="9.23796782399639E-07"
        ixy="-5.2003094782747E-14"
        ixz="-1.4611609987537E-21"
        iyy="8.8589629868825E-07"
        iyz="-1.16610393998141E-22"
        izz="1.34461458261358E-06" />
    </inertial>
    <visual>
      <origin
        xyz="0 0 0"
        rpy="0 0 0" />
      <geometry>
        <mesh
          filename="package://mobile_robot_urdf/meshes/MT_behind_Right.STL" />
      </geometry>
      <material
        name="">
        <color
          rgba="0.690196078431373 0.658823529411765 0.63921568627451 1" />
      </material>
    </visual>
    <collision>
      <origin
        xyz="0 0 0"
        rpy="0 0 0" />
      <geometry>
        <mesh
          filename="package://mobile_robot_urdf/meshes/MT_behind_Right.STL" />
      </geometry>
    </collision>
  </link>
  <joint
    name="MT_behind_Right_jt"
    type="fixed">
    <origin
      xyz="-0.109979375997176 -0.0949999999999994 -0.0190000000000004"
      rpy="0 0 0" />
    <parent
      link="base_link" />
    <child
      link="MT_behind_Right" />
    <axis
      xyz="0 0 0" />
  </joint>
  <link
    name="MT_up_Left">
    <inertial>
      <origin
        xyz="-4.16333634234434E-17 2.77555756156289E-17 0.0127957030881675"
        rpy="0 0 0" />
      <mass
        value="0.0114608893813283" />
      <inertia
        ixx="9.23796782399639E-07"
        ixy="-5.20030944535711E-14"
        ixz="-1.47083723440911E-21"
        iyy="8.85896298688249E-07"
        iyz="3.31467794704133E-23"
        izz="1.34461458261358E-06" />
    </inertial>
    <visual>
      <origin
        xyz="0 0 0"
        rpy="0 0 0" />
      <geometry>
        <mesh
          filename="package://mobile_robot_urdf/meshes/MT_up_Left.STL" />
      </geometry>
      <material
        name="">
        <color
          rgba="0.690196078431373 0.658823529411765 0.63921568627451 1" />
      </material>
    </visual>
    <collision>
      <origin
        xyz="0 0 0"
        rpy="0 0 0" />
      <geometry>
        <mesh
          filename="package://mobile_robot_urdf/meshes/MT_up_Left.STL" />
      </geometry>
    </collision>
  </link>
  <joint
    name="MT_up_Left_jt"
    type="fixed">
    <origin
      xyz="0.110020624002825 0.0949999999999998 -0.0189999999999996"
      rpy="0 0 0" />
    <parent
      link="base_link" />
    <child
      link="MT_up_Left" />
    <axis
      xyz="0 0 0" />
  </joint>
  <link
    name="MT_up_Right">
    <inertial>
      <origin
        xyz="-4.16333634234434E-17 0 0.0127957030881675"
        rpy="0 0 0" />
      <mass
        value="0.0114608893813283" />
      <inertia
        ixx="9.23796782399638E-07"
        ixy="-5.20030942578831E-14"
        ixz="-1.44211671459753E-21"
        iyy="8.85896298688249E-07"
        iyz="-9.86766901150392E-23"
        izz="1.34461458261358E-06" />
    </inertial>
    <visual>
      <origin
        xyz="0 0 0"
        rpy="0 0 0" />
      <geometry>
        <mesh
          filename="package://mobile_robot_urdf/meshes/MT_up_Right.STL" />
      </geometry>
      <material
        name="">
        <color
          rgba="0.690196078431373 0.658823529411765 0.63921568627451 1" />
      </material>
    </visual>
    <collision>
      <origin
        xyz="0 0 0"
        rpy="0 0 0" />
      <geometry>
        <mesh
          filename="package://mobile_robot_urdf/meshes/MT_up_Right.STL" />
      </geometry>
    </collision>
  </link>
  <joint
    name="MT_up_Right_jt"
    type="fixed">
    <origin
      xyz="0.110020624002824 -0.0950000000000002 -0.0189999999999996"
      rpy="0 0 0" />
    <parent
      link="base_link" />
    <child
      link="MT_up_Right" />
    <axis
      xyz="0 0 0" />
  </joint>
  <link
    name="Lidar">
    <inertial>
      <origin
        xyz="0.00613373292374306 -0.000194739234815999 -0.0223629310337731"
        rpy="0 0 0" />
      <mass
        value="0.167234520956808" />
      <inertia
        ixx="7.832979526951E-05"
        ixy="-9.41525292178445E-08"
        ixz="2.21315211543089E-05"
        iyy="0.000121710164909535"
        iyz="-3.97402221956207E-07"
        izz="0.000140309987003384" />
    </inertial>
    <visual>
      <origin
        xyz="0 0 0"
        rpy="0 0 0" />
      <geometry>
        <mesh
          filename="package://mobile_robot_urdf/meshes/Lidar.STL" />
      </geometry>
      <material
        name="">
        <color
          rgba="0.298039215686275 0.298039215686275 0.298039215686275 1" />
      </material>
    </visual>
    <collision>
      <origin
        xyz="0 0 0"
        rpy="0 0 0" />
      <geometry>
        <mesh
          filename="package://mobile_robot_urdf/meshes/Lidar.STL" />
      </geometry>
    </collision>
  </link>
  <joint
    name="Lidar_jt"
    type="fixed">
    <origin
      xyz="-1.64910859423162E-05 9.90809656540859E-05 0.1022"
      rpy="0 0 0" />
    <parent
      link="base_link" />
    <child
      link="Lidar" />
    <axis
      xyz="0 0 0" />
  </joint>
</robot>